<?xml version="1.0" encoding="UTF-8"?>
<!-- Generated by org.testng.reporters.JUnitReportReporter -->
<testsuite hostname="Kokilavani-PC" name="org.Sample.tng.NextApp" tests="3" failures="2" timestamp="29 Nov 2019 12:31:03 GMT" time="11.815" errors="0">
  <testcase name="aditaMain1" time="1.706" classname="org.Sample.tng.NextApp">
    <failure type="java.lang.AssertionError" message="The following asserts failed:
	expected [https://www.adactin.com/HotelApp/] but found [https://www.adactin.com/HotelApp/SearchHotel.php]">
      <![CDATA[java.lang.AssertionError: The following asserts failed:
	expected [https://www.adactin.com/HotelApp/] but found [https://www.adactin.com/HotelApp/SearchHotel.php]
	at org.testng.asserts.SoftAssert.assertAll(SoftAssert.java:43)
	at org.Sample.tng.NextApp.aditaMain1(NextApp.java:56)
	at sun.reflect.NativeMethodAccessorImpl.invoke0(Native Method)
	at sun.reflect.NativeMethodAccessorImpl.invoke(Unknown Source)
	at sun.reflect.DelegatingMethodAccessorImpl.invoke(Unknown Source)
	at java.lang.reflect.Method.invoke(Unknown Source)
	at org.testng.internal.MethodInvocationHelper.invokeMethod(MethodInvocationHelper.java:86)
	at org.testng.internal.Invoker.invokeMethod(Invoker.java:645)
	at org.testng.internal.Invoker.invokeTestMethod(Invoker.java:822)
	at org.testng.internal.Invoker.invokeTestMethods(Invoker.java:1130)
	at org.testng.internal.TestMethodWorker.invokeTestMethods(TestMethodWorker.java:129)
	at org.testng.internal.TestMethodWorker.run(TestMethodWorker.java:112)
	at org.testng.TestRunner.privateRun(TestRunner.java:782)
	at org.testng.TestRunner.run(TestRunner.java:632)
	at org.testng.SuiteRunner.runTest(SuiteRunner.java:366)
	at org.testng.SuiteRunner.runSequentially(SuiteRunner.java:361)
	at org.testng.SuiteRunner.privateRun(SuiteRunner.java:319)
	at org.testng.SuiteRunner.run(SuiteRunner.java:268)
	at org.testng.SuiteRunnerWorker.runSuite(SuiteRunnerWorker.java:52)
	at org.testng.SuiteRunnerWorker.run(SuiteRunnerWorker.java:86)
	at org.testng.TestNG.runSuitesSequentially(TestNG.java:1244)
	at org.testng.TestNG.runSuitesLocally(TestNG.java:1169)
	at org.testng.TestNG.run(TestNG.java:1064)
	at org.testng.remote.RemoteTestNG.run(RemoteTestNG.java:113)
	at org.testng.remote.RemoteTestNG.initAndRun(RemoteTestNG.java:206)
	at org.testng.remote.RemoteTestNG.main(RemoteTestNG.java:177)
]]>
    </failure>
  </testcase> <!-- aditaMain1 -->
  <testcase name="aditaMain1" time="6.973" classname="org.Sample.tng.NextApp">
    <failure type="java.lang.AssertionError" message="The following asserts failed:
	expected [https://www.adactin.com/HotelApp/] but found [https://www.adactin.com/HotelApp/SearchHotel.php]">
      <![CDATA[java.lang.AssertionError: The following asserts failed:
	expected [https://www.adactin.com/HotelApp/] but found [https://www.adactin.com/HotelApp/SearchHotel.php]
	at org.testng.asserts.SoftAssert.assertAll(SoftAssert.java:43)
	at org.Sample.tng.NextApp.aditaMain1(NextApp.java:56)
	at sun.reflect.NativeMethodAccessorImpl.invoke0(Native Method)
	at sun.reflect.NativeMethodAccessorImpl.invoke(Unknown Source)
	at sun.reflect.DelegatingMethodAccessorImpl.invoke(Unknown Source)
	at java.lang.reflect.Method.invoke(Unknown Source)
	at org.testng.internal.MethodInvocationHelper.invokeMethod(MethodInvocationHelper.java:86)
	at org.testng.internal.Invoker.invokeMethod(Invoker.java:645)
	at org.testng.internal.Invoker.invokeTestMethod(Invoker.java:822)
	at org.testng.internal.Invoker.invokeTestMethods(Invoker.java:1130)
	at org.testng.internal.TestMethodWorker.invokeTestMethods(TestMethodWorker.java:129)
	at org.testng.internal.TestMethodWorker.run(TestMethodWorker.java:112)
	at org.testng.TestRunner.privateRun(TestRunner.java:782)
	at org.testng.TestRunner.run(TestRunner.java:632)
	at org.testng.SuiteRunner.runTest(SuiteRunner.java:366)
	at org.testng.SuiteRunner.runSequentially(SuiteRunner.java:361)
	at org.testng.SuiteRunner.privateRun(SuiteRunner.java:319)
	at org.testng.SuiteRunner.run(SuiteRunner.java:268)
	at org.testng.SuiteRunnerWorker.runSuite(SuiteRunnerWorker.java:52)
	at org.testng.SuiteRunnerWorker.run(SuiteRunnerWorker.java:86)
	at org.testng.TestNG.runSuitesSequentially(TestNG.java:1244)
	at org.testng.TestNG.runSuitesLocally(TestNG.java:1169)
	at org.testng.TestNG.run(TestNG.java:1064)
	at org.testng.remote.RemoteTestNG.run(RemoteTestNG.java:113)
	at org.testng.remote.RemoteTestNG.initAndRun(RemoteTestNG.java:206)
	at org.testng.remote.RemoteTestNG.main(RemoteTestNG.java:177)
]]>
    </failure>
  </testcase> <!-- aditaMain1 -->
  <testcase name="aditaMain1" time="3.136" classname="org.Sample.tng.NextApp"/>
</testsuite> <!-- org.Sample.tng.NextApp -->
